2025-05-13 22:13:02 +0000 - dagster - DEBUG - __ASSET_JOB - 615f5e38-3230-41a2-994c-64460797b849 - 8015 - LOGS_CAPTURED - Started capturing logs in process (pid: 8015).
2025-05-13 22:13:02 +0000 - dagster - DEBUG - __ASSET_JOB - 615f5e38-3230-41a2-994c-64460797b849 - 8015 - load_file_to_snowflake - STEP_START - Started execution of step "load_file_to_snowflake".
2025-05-13 22:14:45 +0000 - dagster - ERROR - __ASSET_JOB - 615f5e38-3230-41a2-994c-64460797b849 - 8015 - load_file_to_snowflake - STEP_FAILURE - Execution of step "load_file_to_snowflake" failed.

dagster._core.errors.DagsterExecutionStepExecutionError: Error occurred while executing op "load_file_to_snowflake"::

snowflake.connector.errors.OperationalError: 250001: Could not connect to Snowflake backend after 2 attempt(s).Aborting

Stack Trace:
  File "/usr/local/lib/python3.10/site-packages/dagster/_core/execution/plan/utils.py", line 56, in op_execution_error_boundary
    yield
  File "/usr/local/lib/python3.10/site-packages/dagster/_utils/__init__.py", line 392, in iterate_with_context
    next_output = next(iterator)
  File "/usr/local/lib/python3.10/site-packages/dagster/_core/execution/plan/compute_generator.py", line 129, in _coerce_op_compute_fn_to_iterator
    result = invoke_compute_fn(
  File "/usr/local/lib/python3.10/site-packages/dagster/_core/execution/plan/compute_generator.py", line 117, in invoke_compute_fn
    return fn(context, **args_to_pass) if context_arg_provided else fn(**args_to_pass)
  File "/app/dagster_project/assets/load_file.py", line 11, in load_file_to_snowflake
    conn = snowflake.connector.connect(
  File "/usr/local/lib/python3.10/site-packages/snowflake/connector/__init__.py", line 54, in Connect
    return SnowflakeConnection(**kwargs)
  File "/usr/local/lib/python3.10/site-packages/snowflake/connector/connection.py", line 548, in __init__
    self.connect(**kwargs)
  File "/usr/local/lib/python3.10/site-packages/snowflake/connector/connection.py", line 901, in connect
    self.__open_connection()
  File "/usr/local/lib/python3.10/site-packages/snowflake/connector/connection.py", line 1293, in __open_connection
    self.authenticate_with_retry(self.auth_class)
  File "/usr/local/lib/python3.10/site-packages/snowflake/connector/connection.py", line 1615, in authenticate_with_retry
    self._authenticate(auth_instance)
  File "/usr/local/lib/python3.10/site-packages/snowflake/connector/connection.py", line 1693, in _authenticate
    raise auth_op from e
  File "/usr/local/lib/python3.10/site-packages/snowflake/connector/connection.py", line 1668, in _authenticate
    auth_instance.handle_timeout(
  File "/usr/local/lib/python3.10/site-packages/snowflake/connector/auth/by_plugin.py", line 211, in handle_timeout
    raise error

The above exception was caused by the following exception:
snowflake.connector.errors.OperationalError: 251012: Login request is retryable. Will be handled by authenticator

Stack Trace:
  File "/usr/local/lib/python3.10/site-packages/snowflake/connector/connection.py", line 1647, in _authenticate
    auth.authenticate(
  File "/usr/local/lib/python3.10/site-packages/snowflake/connector/auth/_auth.py", line 226, in authenticate
    ret = self._rest._post_request(
  File "/usr/local/lib/python3.10/site-packages/snowflake/connector/network.py", line 759, in _post_request
    ret = self.fetch(
  File "/usr/local/lib/python3.10/site-packages/snowflake/connector/network.py", line 874, in fetch
    ret = self._request_exec_wrapper(
  File "/usr/local/lib/python3.10/site-packages/snowflake/connector/network.py", line 1002, in _request_exec_wrapper
    raise e
  File "/usr/local/lib/python3.10/site-packages/snowflake/connector/network.py", line 924, in _request_exec_wrapper
    return_object = self._request_exec(
  File "/usr/local/lib/python3.10/site-packages/snowflake/connector/network.py", line 1201, in _request_exec
    raise err
  File "/usr/local/lib/python3.10/site-packages/snowflake/connector/network.py", line 1132, in _request_exec
    raise OperationalError(

